Workbook
Name IQ_CH: 110000
Name IQ_CQ: 5000
Name IQ_CY: 10000
Name IQ_DAILY: 500000
Name IQ_FH: 100000
Name IQ_FQ: 500
Name IQ_FY: 1000
Name IQ_LTM: 2000
Name IQ_MONTH: 15000
Name IQ_NTM: 6000
Name IQ_WEEK: 50000
Name IQ_YTD: 3000

Sheet Cover>

Sheet ControlSheet
B2: Mrs Sector Foods
B3: Control Sheet
F4: Current Case | G4: 1
F8: Actual | G8: Explicit Forecast Period
B9: In INR crores unless started otherwise | F9: 2023 | G9: =F9+1 -> 2024 | H9: =G9+1 -> 2025 | I9: =H9+1 -> 2026 | J9: =I9+1 -> 2027 | K9: =J9+1 -> 2028
A11: # | B11: Sales Assumptions
B13: Cereals
B15: Price/Box - yoy % Growth
B16: Management Case | G16: 0.03 | H16: 0.03 | I16: 0.03 | J16: 0.03 | K16: 0.03
B17: Best Case | G17: 0.04 | H17: 0.04 | I17: 0.04 | J17: 0.04 | K17: 0.04
B18: Down Case | G18: 0.02 | H18: 0.02 | I18: 0.02 | J18: 0.02 | K18: 0.02
B19: ="Current Case - "&CHOOSE($G$4,B16,B17,B18) -> Current Case - Management Case | G19: =CHOOSE($G$4,G16,G17,G18) -> 0.03 | H19: =CHOOSE($G$4,H16,H17,H18) -> 0.03 | I19: =CHOOSE($G$4,I16,I17,I18) -> 0.03 | J19: =CHOOSE($G$4,J16,J17,J18) -> 0.03 | K19: =CHOOSE($G$4,K16,K17,K18) -> 0.03
B21: Number of Boxes Sold - yoy % Growth
B22: Management Case | G22: 0.08 | H22: 0.08 | I22: 0.08 | J22: 0.07 | K22: 0.07
B23: Best Case | G23: 0.09 | H23: 0.09 | I23: 0.09 | J23: 0.09 | K23: 0.09
B24: Down Case | G24: 0.07 | H24: 0.07 | I24: 0.07 | J24: 0.07 | K24: 0.07
B25: ="Current Case - "&CHOOSE($G$4,B22,B23,B24) -> Current Case - Management Case | G25: =CHOOSE($G$4,G22,G23,G24) -> 0.08 | H25: =CHOOSE($G$4,H22,H23,H24) -> 0.08 | I25: =CHOOSE($G$4,I22,I23,I24) -> 0.08 | J25: =CHOOSE($G$4,J22,J23,J24) -> 0.07 | K25: =CHOOSE($G$4,K22,K23,K24) -> 0.07
B27: Pickle
B29: Price/Sachets- yoy % Growth
B30: Management Case | G30: 0.02 | H30: 0.02 | I30: 0.02 | J30: 0.02 | K30: 0.02
B31: Best Case | G31: 0.03 | H31: 0.03 | I31: 0.03 | J31: 0.03 | K31: 0.03
B32: Down Case | G32: 0.01 | H32: 0.01 | I32: 0.01 | J32: 0.01 | K32: 0.01
B33: ="Current Case - "&CHOOSE($G$4,B30,B31,B32) -> Current Case - Management Case | G33: =CHOOSE($G$4,G30,G31,G32) -> 0.02 | H33: =CHOOSE($G$4,H30,H31,H32) -> 0.02 | I33: =CHOOSE($G$4,I30,I31,I32) -> 0.02 | J33: =CHOOSE($G$4,J30,J31,J32) -> 0.02 | K33: =CHOOSE($G$4,K30,K31,K32) -> 0.02
B35: Number of Sachets Sold - yoy % Growth
B36: Management Case | G36: 0.07 | H36: 0.07 | I36: 0.07 | J36: 0.05 | K36: 0.05
B37: Best Case | G37: 0.08 | H37: 0.08 | I37: 0.08 | J37: 0.08 | K37: 0.08
B38: Down Case | G38: 0.06 | H38: 0.06 | I38: 0.06 | J38: 0.06 | K38: 0.06
B39: ="Current Case - "&CHOOSE($G$4,B36,B37,B38) -> Current Case - Management Case | G39: =CHOOSE($G$4,G36,G37,G38) -> 0.07 | H39: =CHOOSE($G$4,H36,H37,H38) -> 0.07 | I39: =CHOOSE($G$4,I36,I37,I38) -> 0.07 | J39: =CHOOSE($G$4,J36,J37,J38) -> 0.05 | K39: =CHOOSE($G$4,K36,K37,K38) -> 0.05
B41: Sauces
B43: Price/Sachets- yoy % Growth
B44: Management Case | G44: 0.01 | H44: 0.01 | I44: 0.01 | J44: 0.01 | K44: 0.01
B45: Best Case | G45: 0.02 | H45: 0.02 | I45: 0.02 | J45: 0.02 | K45: 0.02
B46: Down Case | G46: 0 | H46: 0 | I46: 0 | J46: 0 | K46: 0
B47: ="Current Case - "&CHOOSE($G$4,B44,B45,B46) -> Current Case - Management Case | G47: =CHOOSE($G$4,G44,G45,G46) -> 0.01 | H47: =CHOOSE($G$4,H44,H45,H46) -> 0.01 | I47: =CHOOSE($G$4,I44,I45,I46) -> 0.01 | J47: =CHOOSE($G$4,J44,J45,J46) -> 0.01 | K47: =CHOOSE($G$4,K44,K45,K46) -> 0.01
B49: Number of Sachets Sold - yoy % Growth
B50: Management Case | G50: 0.05 | H50: 0.05 | I50: 0.03 | J50: 0.03 | K50: 0.03
B51: Best Case | G51: 0.06 | H51: 0.06 | I51: 0.06 | J51: 0.06 | K51: 0.06
B52: Down Case | G52: 0.04 | H52: 0.04 | I52: 0.04 | J52: 0.04 | K52: 0.04
B53: ="Current Case - "&CHOOSE($G$4,B50,B51,B52) -> Current Case - Management Case | G53: =CHOOSE($G$4,G50,G51,G52) -> 0.05 | H53: =CHOOSE($G$4,H50,H51,H52) -> 0.05 | I53: =CHOOSE($G$4,I50,I51,I52) -> 0.03 | J53: =CHOOSE($G$4,J50,J51,J52) -> 0.03 | K53: =CHOOSE($G$4,K50,K51,K52) -> 0.03
A55: # | B55: COGS Assumptions
...

Sheet Schedules
B2: Mrs Sector Foods
B3: Control Sheet
E4: Current Case | F4: 1
E8: Actual | F8: Explicit Forecast Period
B9: In INR crores unless started otherwise | E9: 2023 | F9: =E9+1 -> 2024 | G9: =F9+1 -> 2025 | H9: =G9+1 -> 2026 | I9: =H9+1 -> 2027 | J9: =I9+1 -> 2028
A11: # | B11: Sales Schedules
B13: Cereals
B15: Price/Box | E15: 150 | F15: =E15*(1+F19) -> 154.5 | G15: =F15*(1+G19) -> 159.135 | H15: =G15*(1+H19) -> 163.90905 | I15: =H15*(1+I19) -> 168.82632 | J15: =I15*(1+J19) -> 173.89111
B16: Number of boxes Sold (in crs) | E16: 279 | F16: =E16*(1+F20) -> 301.32 | G16: =F16*(1+G20) -> 325.4256 | H16: =G16*(1+H20) -> 351.45965 | I16: =H16*(1+I20) -> 376.06182 | J16: =I16*(1+J20) -> 402.38615
B17: Total Sales - Cereals | E17: =E16*E15 -> 41850 | F17: =F16*F15 -> 46553.94 | G17: =G16*G15 -> 51786.603 | H17: =H16*H15 -> 57607.417 | I17: =I16*I15 -> 63489.134 | J17: =J16*J15 -> 69971.375
B19: Price growth % y-o-y | F19: =ControlSheet!G19 -> 0.03 | G19: =ControlSheet!G19 -> 0.03 | H19: =ControlSheet!H19 -> 0.03 | I19: =ControlSheet!I19 -> 0.03 | J19: =ControlSheet!J19 -> 0.03
B20: Volume growth % y-o-y | F20: =ControlSheet!G25 -> 0.08 | G20: =ControlSheet!H25 -> 0.08 | H20: =ControlSheet!I25 -> 0.08 | I20: =ControlSheet!J25 -> 0.07 | J20: =ControlSheet!K25 -> 0.07
B21: Total Sales - Cereals growth % y-o-y | F21: =F17/E17-1 -> 0.1124 | G21: =G17/F17-1 -> 0.1124 | H21: =H17/G17-1 -> 0.1124 | I21: =I17/H17-1 -> 0.1021 | J21: =J17/I17-1 -> 0.1021
B23: Pickle
B25: Price/Box | E25: 50 | F25: =E25*(1+F29) -> 51 | G25: =F25*(1+G29) -> 52.02 | H25: =G25*(1+H29) -> 53.0604 | I25: =H25*(1+I29) -> 54.121608 | J25: =I25*(1+J29) -> 55.20404
B26: Number of boxes Sold (in crs) | E26: 217 | F26: =E26*(1+F30) -> 232.19 | G26: =F26*(1+G30) -> 248.4433 | H26: =G26*(1+H30) -> 265.83433 | I26: =H26*(1+I30) -> 279.12605 | J26: =I26*(1+J30) -> 293.08235
B27: Total Sales - Pickle | E27: =E26*E25 -> 10850 | F27: =F26*F25 -> 11841.69 | G27: =G26*G25 -> 12924.02 | H27: =H26*H25 -> 14105.276 | I27: =I26*I25 -> 15106.751 | J27: =J26*J25 -> 16179.33
B29: Price growth % y-o-y | F29: =ControlSheet!G33 -> 0.02 | G29: =ControlSheet!H33 -> 0.02 | H29: =ControlSheet!I33 -> 0.02 | I29: =ControlSheet!J33 -> 0.02 | J29: =ControlSheet!K33 -> 0.02
B30: Volume growth % y-o-y | F30: =ControlSheet!G39 -> 0.07 | G30: =ControlSheet!H39 -> 0.07 | H30: =ControlSheet!I39 -> 0.07 | I30: =ControlSheet!J39 -> 0.05 | J30: =ControlSheet!K39 -> 0.05
B31: Total Sales - Pickle growth % y-o-y | F31: =F27/E27-1 -> 0.0914 | G31: =G27/F27-1 -> 0.0914 | H31: =H27/G27-1 -> 0.0914 | I31: =I27/H27-1 -> 0.071 | J31: =J27/I27-1 -> 0.071
B33: Sauces
B35: Price/Box | E35: 30 | F35: =E35*(1+F39) -> 30.3 | G35: =F35*(1+G39) -> 30.603 | H35: =G35*(1+H39) -> 30.90903 | I35: =H35*(1+I39) -> 31.21812 | J35: =I35*(1+J39) -> 31.530302
B36: Number of boxes Sold (in crs) | E36: 177 | F36: =E36*(1+F40) -> 185.85 | G36: =F36*(1+G40) -> 195.1425 | H36: =G36*(1+H40) -> 200.99678 | I36: =H36*(1+I40) -> 207.02668 | J36: =I36*(1+J40) -> 213.23748
B37: Total Sales - Sauces | E37: =E36*E35 -> 5310 | F37: =F36*F35 -> 5631.255 | G37: =G36*G35 -> 5971.9459 | H37: =H36*H35 -> 6212.6153 | I37: =I36*I35 -> 6462.9837 | J37: =J36*J35 -> 6723.442
B39: Price growth % y-o-y | F39: =ControlSheet!G47 -> 0.01 | G39: =ControlSheet!H47 -> 0.01 | H39: =ControlSheet!I47 -> 0.01 | I39: =ControlSheet!J47 -> 0.01 | J39: =ControlSheet!K47 -> 0.01
B40: Volume growth % y-o-y | F40: =ControlSheet!G53 -> 0.05 | G40: =ControlSheet!H53 -> 0.05 | H40: =ControlSheet!I53 -> 0.03 | I40: =ControlSheet!J53 -> 0.03 | J40: =ControlSheet!K53 -> 0.03
B41: Total Sales - Sauces growth % y-o-y | F41: =F37/E37-1 -> 0.0605 | G41: =G37/F37-1 -> 0.0605 | H41: =H37/G37-1 -> 0.0403 | I41: =I37/H37-1 -> 0.0403 | J41: =J37/I37-1 -> 0.0403
B44: Total Sales | E44: =E37+E27+E17 -> 58010 | F44: =F37+F27+F17 -> 64026.885 | G44: =G37+G27+G17 -> 70682.569 | H44: =H37+H27+H17 -> 77925.308 | I44: =I37+I27+I17 -> 85058.869 | J44: =J37+J27+J17 -> 92874.147
B45: Total Sales - growth % y-o-y | F45: =F44/E44-1 -> 0.10372151 | G45: =G44/F44-1 -> 0.1039514 | H45: =H44/G44-1 -> 0.10246853 | I45: =I44/H44-1 -> 0.091543562 | J45: =J44/I44-1 -> 0.091880815
A48: # | B48: COGS Schedules
B50: Cereals
B52: Total Boxes Sold | E52: =E16 -> 279 | F52: =F16 -> 301.32 | G52: =G16 -> 325.4256 | H52: =H16 -> 351.45965 | I52: =I16 -> 376.06182 | J52: =J16 -> 402.38615
B54: Raw Material Cost/Box | E54: 27.5 | F54: =E54*(1+F68) -> 27.5 | G54: =F54*(1+G68) -> 27.5 | H54: =G54*(1+H68) -> 27.5 | I54: =H54*(1+I68) -> 27.5 | J54: =I54*(1+J68) -> 27.5
B55: Total Raw Material Cost | E55: =E54*E$52 -> 7672.5 | F55: =F54*F$52 -> 8286.3 | G55: =G54*G$52 -> 8949.204 | H55: =H54*H$52 -> 9665.1403 | I55: =I54*I$52 -> 10341.7 | J55: =J52*J54 -> 11065.619
B57: Labour Cost/Box | E57: 10 | F57: =E57*(1+F69) -> 10 | G57: =F57*(1+G69) -> 10 | H57: =G57*(1+H69) -> 10 | I57: =H57*(1+I69) -> 10 | J57: =I57*(1+J69) -> 10
B58: Total Labour Cost | E58: =E57*E$52 -> 2790 | F58: =F57*F$52 -> 3013.2 | G58: =G57*G$52 -> 3254.256 | H58: =H57*H$52 -> 3514.5965 | I58: =I57*I$52 -> 3760.6182 | J58: =J57*J$52 -> 4023.8615
B60: Packaging Cost/Box | E60: 12.5 | F60: =E60*(1+F70) -> 12.5 | G60: =F60*(1+G70) -> 12.5 | H60: =G60*(1+H70) -> 12.5 | I60: =H60*(1+I70) -> 12.5 | J60: =I60*(1+J70) -> 12.5
B61: Total Packaging Cost | E61: =E60*E$52 -> 3487.5 | F61: =F60*F$52 -> 3766.5 | G61: =G60*G$52 -> 4067.82 | H61: =H60*H$52 -> 4393.2456 | I61: =I60*I$52 -> 4700.7728 | J61: =J60*J$52 -> 5029.8269
B63: Delivery Cost/Box | E63: 8 | F63: =E63*(1+F71) -> 8 | G63: =F63*(1+G71) -> 8 | H63: =G63*(1+H71) -> 8 | I63: =H63*(1+I71) -> 8 | J63: =I63*(1+J71) -> 8
B64: Total Delivery Cost | E64: =E63*E$52 -> 2232 | F64: =F63*F$52 -> 2410.56 | G64: =G63*G$52 -> 2603.4048 | H64: =H63*H$52 -> 2811.6772 | I64: =I63*I$52 -> 3008.4946 | J64: =J63*J$52 -> 3219.0892
...

Sheet 3 Statement Model
B2: Mrs Sector Foods
B3: 3 Statement Model
F4: Current Case | G4: 1
I5: =G49/G62 -> 0.091450866
M7: CAGR
D8: Actual | G8: Explicit Forecast Period | M8: 5 Year | N8: 3 Year
B9: In INR crores unless started otherwise | D9: 2021 | E9: =D9+1 -> 2022 | F9: =E9+1 -> 2023 | G9: =F9+1 -> 2024 | H9: =G9+1 -> 2025 | I9: =H9+1 -> 2026 | J9: =I9+1 -> 2027 | K9: =J9+1 -> 2028
A11: # | B11: Income Statement
B13: Revenue | D13: =INDEX(' Income Statement'!$E$8:$G$27,MATCH('3 Statement Model'!$B13,' Income Statement'!$B$8:$B$27,0),MATCH('3 Statement Model'!D$9,' Income Statement'!$E$6:$G$6,0)) -> 47325.572 | E13: =INDEX(' Income Statement'!$E$8:$G$27,MATCH('3 Statement Model'!$B13,' Income Statement'!$B$8:$B$27,0),MATCH('3 Statement Model'!E$9,' Income Statement'!$E$6:$G$6,0)) -> 52562.986 | F13: =INDEX(' Income Statement'!$E$8:$G$27,MATCH('3 Statement Model'!$B13,' Income Statement'!$B$8:$B$27,0),MATCH('3 Statement Model'!F$9,' Income Statement'!$E$6:$G$6,0)) -> 58055.612 | G13: =Schedules!F44 -> 64026.885 | H13: =Schedules!G44 -> 70682.569 | I13: =Schedules!H44 -> 77925.308 | J13: =Schedules!I44 -> 85058.869 | K13: =Schedules!J44 -> 92874.147 | M13: =_xlfn.RRI($K$9-$F$9,F13,K13) -> 0.098525459 | N13: =_xlfn.RRI($K$9-$H$9,H13,K13) -> 0.095285916
B14: Less: Cost of Goods Sold | D14: =INDEX(' Income Statement'!$E$8:$G$27,MATCH('3 Statement Model'!$B14,' Income Statement'!$B$8:$B$27,0),MATCH('3 Statement Model'!D$9,' Income Statement'!$E$6:$G$6,0)) -> -24230.696 | E14: =INDEX(' Income Statement'!$E$8:$G$27,MATCH('3 Statement Model'!$B14,' Income Statement'!$B$8:$B$27,0),MATCH('3 Statement Model'!E$9,' Income Statement'!$E$6:$G$6,0)) -> -26556.942 | F14: =INDEX(' Income Statement'!$E$8:$G$27,MATCH('3 Statement Model'!$B14,' Income Statement'!$B$8:$B$27,0),MATCH('3 Statement Model'!F$9,' Income Statement'!$E$6:$G$6,0)) -> -28130.39 | G14: =Schedules!F128*-1 -> -30164.898 | H14: =Schedules!G128*-1 -> -32368.842 | I14: =Schedules!H128*-1 -> -34640.689 | J14: =Schedules!I128*-1 -> -36690.979 | K14: =Schedules!J128*-1 -> -38869.545 | M14: =_xlfn.RRI($K$9-$F$9,F14,K14) -> 0.066809168 | N14: =_xlfn.RRI($K$9-$H$9,H14,K14) -> 0.062904135
B15: Gross Profit | D15: =SUM(D13:D14) -> 23094.876 | E15: =SUM(E13:E14) -> 26006.044 | F15: =SUM(F13:F14) -> 29925.221 | G15: =SUM(G13:G14) -> 33861.987 | H15: =SUM(H13:H14) -> 38313.727 | I15: =SUM(I13:I14) -> 43284.619 | J15: =SUM(J13:J14) -> 48367.89 | K15: =SUM(K13:K14) -> 54004.602 | M15: =_xlfn.RRI($K$9-$F$9,F15,K15) -> 0.12532685 | N15: =_xlfn.RRI($K$9-$H$9,H15,K15) -> 0.12122332
B17: Less: SG&A Expenses (Excluding Depreciation & Interest)
B18: Administrative Costs | D18: =INDEX(' Income Statement'!$E$8:$G$27,MATCH('3 Statement Model'!$B18,' Income Statement'!$B$8:$B$27,0),MATCH('3 Statement Model'!D$9,' Income Statement'!$E$6:$G$6,0)) -> -285.278 | E18: =INDEX(' Income Statement'!$E$8:$G$27,MATCH('3 Statement Model'!$B18,' Income Statement'!$B$8:$B$27,0),MATCH('3 Statement Model'!E$9,' Income Statement'!$E$6:$G$6,0)) -> -314.776 | F18: =INDEX(' Income Statement'!$E$8:$G$27,MATCH('3 Statement Model'!$B18,' Income Statement'!$B$8:$B$27,0),MATCH('3 Statement Model'!F$9,' Income Statement'!$E$6:$G$6,0)) -> -347.6648 | G18: =Schedules!F172*-1 -> -640.26885 | H18: =Schedules!G172*-1 -> -706.82569 | I18: =Schedules!H172*-1 -> -779.25308 | J18: =Schedules!I172*-1 -> -850.58869 | K18: =Schedules!J172*-1 -> -928.74147 | M18: =_xlfn.RRI($K$9-$F$9,F18,K18) -> 0.21715762 | N18: =_xlfn.RRI($K$9-$H$9,H18,K18) -> 0.095285916
B19: Executive Compensation | D19: =INDEX(' Income Statement'!$E$8:$G$27,MATCH('3 Statement Model'!$B19,' Income Statement'!$B$8:$B$27,0),MATCH('3 Statement Model'!D$9,' Income Statement'!$E$6:$G$6,0)) -> -2602.8996 | E19: =INDEX(' Income Statement'!$E$8:$G$27,MATCH('3 Statement Model'!$B19,' Income Statement'!$B$8:$B$27,0),MATCH('3 Statement Model'!E$9,' Income Statement'!$E$6:$G$6,0)) -> -2733.2592 | F19: =INDEX(' Income Statement'!$E$8:$G$27,MATCH('3 Statement Model'!$B19,' Income Statement'!$B$8:$B$27,0),MATCH('3 Statement Model'!F$9,' Income Statement'!$E$6:$G$6,0)) -> -2902.7796 | G19: =Schedules!F183*-1 -> -3420.2065 | H19: =Schedules!G183*-1 -> -3649.8651 | I19: =Schedules!H183*-1 -> -3897.735 | J19: =Schedules!I183*-1 -> -4142.9413 | K19: =Schedules!J183*-1 -> -4409.2232 | M19: =_xlfn.RRI($K$9-$F$9,F19,K19) -> 0.087200401 | N19: =_xlfn.RRI($K$9-$H$9,H19,K19) -> 0.065029794
B20: Marketing Costs | D20: =INDEX(' Income Statement'!$E$8:$G$27,MATCH('3 Statement Model'!$B20,' Income Statement'!$B$8:$B$27,0),MATCH('3 Statement Model'!D$9,' Income Statement'!$E$6:$G$6,0)) -> -1183.1344 | E20: =INDEX(' Income Statement'!$E$8:$G$27,MATCH('3 Statement Model'!$B20,' Income Statement'!$B$8:$B$27,0),MATCH('3 Statement Model'!E$9,' Income Statement'!$E$6:$G$6,0)) -> -1314.0624 | F20: =INDEX(' Income Statement'!$E$8:$G$27,MATCH('3 Statement Model'!$B20,' Income Statement'!$B$8:$B$27,0),MATCH('3 Statement Model'!F$9,' Income Statement'!$E$6:$G$6,0)) -> -1451.38 | G20: =Schedules!F177*-1 -> -1600.6721 | H20: =Schedules!G177*-1 -> -1767.0642 | I20: =Schedules!H177*-1 -> -1948.1327 | J20: =Schedules!I177*-1 -> -2126.4717 | K20: =Schedules!J177*-1 -> -2321.8537 | M20: =_xlfn.RRI($K$9-$F$9,F20,K20) -> 0.098527017 | N20: =_xlfn.RRI($K$9-$H$9,H20,K20) -> 0.095285916
B21: Rent | D21: =INDEX(' Income Statement'!$E$8:$G$27,MATCH('3 Statement Model'!$B21,' Income Statement'!$B$8:$B$27,0),MATCH('3 Statement Model'!D$9,' Income Statement'!$E$6:$G$6,0)) -> -1216.9248 | E21: =INDEX(' Income Statement'!$E$8:$G$27,MATCH('3 Statement Model'!$B21,' Income Statement'!$B$8:$B$27,0),MATCH('3 Statement Model'!E$9,' Income Statement'!$E$6:$G$6,0)) -> -1261.4952 | F21: =INDEX(' Income Statement'!$E$8:$G$27,MATCH('3 Statement Model'!$B21,' Income Statement'!$B$8:$B$27,0),MATCH('3 Statement Model'!F$9,' Income Statement'!$E$6:$G$6,0)) -> -1274 | G21: =Schedules!F158*-1 -> -1274 | H21: =Schedules!G158*-1 -> -1574 | I21: =Schedules!H158*-1 -> -1574 | J21: =Schedules!I158*-1 -> -1574 | K21: =Schedules!J158*-1 -> -1574 | M21: =_xlfn.RRI($K$9-$F$9,F21,K21) -> 0.043198755 | N21: =_xlfn.RRI($K$9-$H$9,H21,K21) -> 0
B22: Retailer Commission | D22: =INDEX(' Income Statement'!$E$8:$G$27,MATCH('3 Statement Model'!$B22,' Income Statement'!$B$8:$B$27,0),MATCH('3 Statement Model'!D$9,' Income Statement'!$E$6:$G$6,0)) -> -7098.8378 | E22: =INDEX(' Income Statement'!$E$8:$G$27,MATCH('3 Statement Model'!$B22,' Income Statement'!$B$8:$B$27,0),MATCH('3 Statement Model'!E$9,' Income Statement'!$E$6:$G$6,0)) -> -7884.4332 | F22: =INDEX(' Income Statement'!$E$8:$G$27,MATCH('3 Statement Model'!$B22,' Income Statement'!$B$8:$B$27,0),MATCH('3 Statement Model'!F$9,' Income Statement'!$E$6:$G$6,0)) -> -8708.3388 | G22: =Schedules!F167*-1 -> -9604.0328 | H22: =Schedules!G167*-1 -> -10602.385 | I22: =Schedules!H167*-1 -> -11688.796 | J22: =Schedules!I167*-1 -> -13609.419 | K22: =Schedules!J167*-1 -> -14859.863 | M22: =_xlfn.RRI($K$9-$F$9,F22,K22) -> 0.11279688 | N22: =_xlfn.RRI($K$9-$H$9,H22,K22) -> 0.1191039
B23: Salaries and Wages | D23: =INDEX(' Income Statement'!$E$8:$G$27,MATCH('3 Statement Model'!$B23,' Income Statement'!$B$8:$B$27,0),MATCH('3 Statement Model'!D$9,' Income Statement'!$E$6:$G$6,0)) -> -4862.27 | E23: =INDEX(' Income Statement'!$E$8:$G$27,MATCH('3 Statement Model'!$B23,' Income Statement'!$B$8:$B$27,0),MATCH('3 Statement Model'!E$9,' Income Statement'!$E$6:$G$6,0)) -> -5151.1544 | F23: =INDEX(' Income Statement'!$E$8:$G$27,MATCH('3 Statement Model'!$B23,' Income Statement'!$B$8:$B$27,0),MATCH('3 Statement Model'!F$9,' Income Statement'!$E$6:$G$6,0)) -> -5711.2832 | G23: =Schedules!F162*-1 -> -5762.4196 | H23: =Schedules!G162*-1 -> -6361.4312 | I23: =Schedules!H162*-1 -> -7013.2777 | J23: =Schedules!I162*-1 -> -7655.2982 | K23: =Schedules!J162*-1 -> -8358.6732 | M23: =_xlfn.RRI($K$9-$F$9,F23,K23) -> 0.079147304 | N23: =_xlfn.RRI($K$9-$H$9,H23,K23) -> 0.095285916
B24: EBITDA | D24: =SUM(D15,D18:D23) -> 5845.5314 | E24: =SUM(E15,E18:E23) -> 7346.864 | F24: =SUM(F15,F18:F23) -> 9529.7748 | G24: =SUM(G15,G18:G23) -> 11560.387 | H24: =SUM(H15,H18:H23) -> 13652.155 | I24: =SUM(I15,I18:I23) -> 16383.425 | J24: =SUM(J15,J18:J23) -> 18409.171 | K24: =SUM(K15,K18:K23) -> 21552.247 | M24: =_xlfn.RRI($K$9-$F$9,F24,K24) -> 0.17728601 | N24: =_xlfn.RRI($K$9-$H$9,H24,K24) -> 0.16438636
B26: Less: Depreciation & Amortization
B27: Depreciation | D27: =INDEX(' Income Statement'!$E$8:$G$27,MATCH('3 Statement Model'!$B27,' Income Statement'!$B$8:$B$27,0),MATCH('3 Statement Model'!D$9,' Income Statement'!$E$6:$G$6,0)) -> -716.086 | E27: =INDEX(' Income Statement'!$E$8:$G$27,MATCH('3 Statement Model'!$B27,' Income Statement'!$B$8:$B$27,0),MATCH('3 Statement Model'!E$9,' Income Statement'!$E$6:$G$6,0)) -> -735.8624 | F27: =INDEX(' Income Statement'!$E$8:$G$27,MATCH('3 Statement Model'!$B27,' Income Statement'!$B$8:$B$27,0),MATCH('3 Statement Model'!F$9,' Income Statement'!$E$6:$G$6,0)) -> -783.3728 | G27: =Schedules!F224*-1 -> -1103.5072 | H27: =Schedules!G224*-1 -> -1456.9201 | I27: =Schedules!H224*-1 -> -1846.5466 | J27: =Schedules!I224*-1 -> -2271.841 | K27: =Schedules!J224*-1 -> -2736.2117 | M27: =_xlfn.RRI($K$9-$F$9,F27,K27) -> 0.28421057 | N27: =_xlfn.RRI($K$9-$H$9,H27,K27) -> 0.23378075
B28: Amortization | D28: =INDEX(' Income Statement'!$E$8:$G$27,MATCH('3 Statement Model'!$B28,' Income Statement'!$B$8:$B$27,0),MATCH('3 Statement Model'!D$9,' Income Statement'!$E$6:$G$6,0)) -> -294.4116 | E28: =INDEX(' Income Statement'!$E$8:$G$27,MATCH('3 Statement Model'!$B28,' Income Statement'!$B$8:$B$27,0),MATCH('3 Statement Model'!E$9,' Income Statement'!$E$6:$G$6,0)) -> -268.9512 | F28: =INDEX(' Income Statement'!$E$8:$G$27,MATCH('3 Statement Model'!$B28,' Income Statement'!$B$8:$B$27,0),MATCH('3 Statement Model'!F$9,' Income Statement'!$E$6:$G$6,0)) -> -232.2208 | G28: =Schedules!F235*-1 -> -360.27457 | H28: =Schedules!G235*-1 -> -501.63971 | I28: =Schedules!H235*-1 -> -657.49033 | J28: =Schedules!I235*-1 -> -827.60806 | K28: =Schedules!J235*-1 -> -1013.3564 | M28: =_xlfn.RRI($K$9-$F$9,F28,K28) -> 0.34267906 | N28: =_xlfn.RRI($K$9-$H$9,H28,K28) -> 0.26412522
B29: EBIT | D29: =SUM(D24,D27:D28) -> 4835.0338 | E29: =SUM(E24,E27:E28) -> 6342.0504 | F29: =SUM(F24,F27:F28) -> 8514.1812 | G29: =SUM(G24,G27:G28) -> 10096.605 | H29: =SUM(H24,H27:H28) -> 11693.596 | I29: =SUM(I24,I27:I28) -> 13879.388 | J29: =SUM(J24,J27:J28) -> 15309.722 | K29: =SUM(K24,K27:K28) -> 17802.679 | M29: =_xlfn.RRI($K$9-$F$9,F29,K29) -> 0.15896012 | N29: =_xlfn.RRI($K$9-$H$9,H29,K29) -> 0.15039176
B31: Less: Total Interest Expenses
B32: Loan Interest Expenses | D32: =INDEX(' Income Statement'!$E$8:$G$27,MATCH('3 Statement Model'!$B32,' Income Statement'!$B$8:$B$27,0),MATCH('3 Statement Model'!D$9,' Income Statement'!$E$6:$G$6,0)) -> -336.924 | E32: =INDEX(' Income Statement'!$E$8:$G$27,MATCH('3 Statement Model'!$B32,' Income Statement'!$B$8:$B$27,0),MATCH('3 Statement Model'!E$9,' Income Statement'!$E$6:$G$6,0)) -> -307.818 | F32: =INDEX(' Income Statement'!$E$8:$G$27,MATCH('3 Statement Model'!$B32,' Income Statement'!$B$8:$B$27,0),MATCH('3 Statement Model'!F$9,' Income Statement'!$E$6:$G$6,0)) -> -278.712 | G32: =-Schedules!F352 -> -653.1672 | H32: =-Schedules!G352 -> -707.0544 | I32: =-Schedules!H352 -> -733.3716 | J32: =-Schedules!I352 -> -733.1688 | K32: =-Schedules!J352 -> -732.446 | M32: =_xlfn.RRI($K$9-$F$9,F32,K32) -> 0.2131765 | N32: =_xlfn.RRI($K$9-$H$9,H32,K32) -> 0.011830099
B33: Rovolver Interest | D33: 0 | E33: 0 | F33: 0 | G33: =Schedules!F353 -> 0 | H33: 0 | I33: 0 | J33: 0 | K33: 0 | M33: =_xlfn.RRI($K$9-$F$9,F33,K33) -> 0 | N33: =_xlfn.RRI($K$9-$H$9,H33,K33) -> 0
B34: EBT | D34: =SUM(D29,D32:D33) -> 4498.1098 | E34: =SUM(E29,E32:E33) -> 6034.2324 | F34: =SUM(F29,F32:F33) -> 8235.4692 | G34: =SUM(G29,G32:G33) -> 9443.4378 | H34: =SUM(H29,H32:H33) -> 10986.541 | I34: =SUM(I29,I32:I33) -> 13146.016 | J34: =SUM(J29,J32:J33) -> 14576.553 | K34: =SUM(K29,K32:K33) -> 17070.233 | M34: =_xlfn.RRI($K$9-$F$9,F34,K34) -> 0.15693836 | N34: =_xlfn.RRI($K$9-$H$9,H34,K34) -> 0.15822469
B36: Less: Taxes | D36: =INDEX(' Income Statement'!$E$8:$G$27,MATCH('3 Statement Model'!$B36,' Income Statement'!$B$8:$B$27,0),MATCH('3 Statement Model'!D$9,' Income Statement'!$E$6:$G$6,0)) -> -906.36913 | E36: =INDEX(' Income Statement'!$E$8:$G$27,MATCH('3 Statement Model'!$B36,' Income Statement'!$B$8:$B$27,0),MATCH('3 Statement Model'!E$9,' Income Statement'!$E$6:$G$6,0)) -> -1215.8978 | F36: =INDEX(' Income Statement'!$E$8:$G$27,MATCH('3 Statement Model'!$B36,' Income Statement'!$B$8:$B$27,0),MATCH('3 Statement Model'!F$9,' Income Statement'!$E$6:$G$6,0)) -> -1659.447 | G36: =Schedules!F256 -> -2360.8595 | H36: =Schedules!G256 -> -2746.6353 | I36: =Schedules!H256 -> -3286.504 | J36: =Schedules!I256 -> -3644.1383 | K36: =Schedules!J256 -> -4267.5582 | M36: =_xlfn.RRI($K$9-$F$9,F36,K36) -> 0.20793401 | N36: =_xlfn.RRI($K$9-$H$9,H36,K36) -> 0.15822469
B37: Net Income | D37: =SUM(D34,D36) -> 3591.7407 | E37: =SUM(E34,E36) -> 4818.3346 | F37: =SUM(F34,F36) -> 6576.0222 | G37: =SUM(G34,G36) -> 7082.5784 | H37: =SUM(H34,H36) -> 8239.9059 | I37: =SUM(I34,I36) -> 9859.512 | J37: =SUM(J34,J36) -> 10932.415 | K37: =SUM(K34,K36) -> 12802.675 | M37: =_xlfn.RRI($K$9-$F$9,F37,K37) -> 0.14252967 | N37: =_xlfn.RRI($K$9-$H$9,H37,K37) -> 0.15822469
B39: Sales Growth % | D39: =IFERROR(D13/C13-1,"NM") -> NM | E39: =IFERROR(E13/D13-1,"NM") -> 0.11066774 | F39: =IFERROR(F13/E13-1,"NM") -> 0.10449607 | G39: =IFERROR(G13/F13-1,"NM") -> 0.10285437 | H39: =IFERROR(H13/G13-1,"NM") -> 0.1039514 | I39: =IFERROR(I13/H13-1,"NM") -> 0.10246853 | J39: =IFERROR(J13/I13-1,"NM") -> 0.091543562 | K39: =IFERROR(K13/J13-1,"NM") -> 0.091880815
B40: Gross Profit Margin % | D40: =IFERROR(D15/D13,"NM") -> 0.48799993 | E40: =IFERROR(E15/E13,"NM") -> 0.49475965 | F40: =IFERROR(F15/F13,"NM") -> 0.51545786 | G40: =IFERROR(G15/G13,"NM") -> 0.52887138 | H40: =IFERROR(H15/H13,"NM") -> 0.5420534 | I40: =IFERROR(I15/I13,"NM") -> 0.55546292 | J40: =IFERROR(J15/J13,"NM") -> 0.56864018 | K40: =IFERROR(K15/K13,"NM") -> 0.58148154
B41: EBITDA Margin % | D41: =IFERROR(D24/D13,"NM") -> 0.1235174 | E41: =IFERROR(E24/E13,"NM") -> 0.13977258 | F41: =IFERROR(F24/F13,"NM") -> 0.16414907 | G41: =IFERROR(G24/G13,"NM") -> 0.1805552 | H41: =IFERROR(H24/H13,"NM") -> 0.19314741 | I41: =IFERROR(I24/I13,"NM") -> 0.21024523 | J41: =IFERROR(J24/J13,"NM") -> 0.21642859 | K41: =IFERROR(K24/K13,"NM") -> 0.23205863
B42: EBIT Margin % | D42: =IFERROR(D29/D13,"NM") -> 0.10216535 | E42: =IFERROR(E29/E13,"NM") -> 0.1206562 | F42: =IFERROR(F29/F13,"NM") -> 0.14665561 | G42: =IFERROR(G29/G13,"NM") -> 0.15769321 | H42: =IFERROR(H29/H13,"NM") -> 0.16543818 | I42: =IFERROR(I29/I13,"NM") -> 0.17811142 | J42: =IFERROR(J29/J13,"NM") -> 0.17998972 | K42: =IFERROR(K29/K13,"NM") -> 0.19168606
B43: Actual Tax Rate % | D43: =-IFERROR(D36/D34,"NM") -> 0.2015 | E43: =-IFERROR(E36/E34,"NM") -> 0.2015 | F43: =-IFERROR(F36/F34,"NM") -> 0.2015 | G43: =-IFERROR(G36/G34,"NM") -> 0.25 | H43: =-IFERROR(H36/H34,"NM") -> 0.25 | I43: =-IFERROR(I36/I34,"NM") -> 0.25 | J43: =-IFERROR(J36/J34,"NM") -> 0.25 | K43: =-IFERROR(K36/K34,"NM") -> 0.25
B44: Net Income Margin % | D44: =IFERROR(D37/D13,"NM") -> 0.07589429 | E44: =IFERROR(E37/E13,"NM") -> 0.091667824 | F44: =IFERROR(F37/F13,"NM") -> 0.11327109 | G44: =IFERROR(G37/G13,"NM") -> 0.11061882 | H44: =IFERROR(H37/H13,"NM") -> 0.11657621 | I44: =IFERROR(I37/I13,"NM") -> 0.12652516 | J44: =IFERROR(J37/J13,"NM") -> 0.12852763 | K44: =IFERROR(K37/K13,"NM") -> 0.13784971
A46: # | B46: Balance Sheet
B48: Assets
B49: Cash | D49: =INDEX(' Balance Sheet'!$E$9:$G$40,MATCH('3 Statement Model'!$B49,' Balance Sheet'!$B$9:$B$40,0),MATCH('3 Statement Model'!D$9,' Balance Sheet'!$E$6:$G$6,0)) -> 1471.2348 | E49: =INDEX(' Balance Sheet'!$E$9:$G$40,MATCH('3 Statement Model'!$B49,' Balance Sheet'!$B$9:$B$40,0),MATCH('3 Statement Model'!E$9,' Balance Sheet'!$E$6:$G$6,0)) -> 1956.0604 | F49: =INDEX(' Balance Sheet'!$E$9:$G$40,MATCH('3 Statement Model'!$B49,' Balance Sheet'!$B$9:$B$40,0),MATCH('3 Statement Model'!F$9,' Balance Sheet'!$E$6:$G$6,0)) -> 2181.2644 | G49: =G116 -> 3386.2058 | H49: =H116 -> 5257.902 | I49: =I116 -> 7677.0036 | J49: =J116 -> 10878.163 | K49: =K116 -> 15353.393
B50: Inventory | D50: =INDEX(' Balance Sheet'!$E$9:$G$40,MATCH('3 Statement Model'!$B50,' Balance Sheet'!$B$9:$B$40,0),MATCH('3 Statement Model'!D$9,' Balance Sheet'!$E$6:$G$6,0)) -> 4686.8108 | E50: =INDEX(' Balance Sheet'!$E$9:$G$40,MATCH('3 Statement Model'!$B50,' Balance Sheet'!$B$9:$B$40,0),MATCH('3 Statement Model'!E$9,' Balance Sheet'!$E$6:$G$6,0)) -> 5155.486 | F50: =INDEX(' Balance Sheet'!$E$9:$G$40,MATCH('3 Statement Model'!$B50,' Balance Sheet'!$B$9:$B$40,0),MATCH('3 Statement Model'!F$9,' Balance Sheet'!$E$6:$G$6,0)) -> 5592.6248 | G50: =Schedules!F280 -> 6000.7099 | H50: =Schedules!G280 -> 6439.141 | I50: =Schedules!H280 -> 6891.08 | J50: =Schedules!I280 -> 7298.9445 | K50: =Schedules!J280 -> 7732.3272
B51: Debtors | D51: =INDEX(' Balance Sheet'!$E$9:$G$40,MATCH('3 Statement Model'!$B51,' Balance Sheet'!$B$9:$B$40,0),MATCH('3 Statement Model'!D$9,' Balance Sheet'!$E$6:$G$6,0)) -> 5476.2792 | E51: =INDEX(' Balance Sheet'!$E$9:$G$40,MATCH('3 Statement Model'!$B51,' Balance Sheet'!$B$9:$B$40,0),MATCH('3 Statement Model'!E$9,' Balance Sheet'!$E$6:$G$6,0)) -> 6023.9032 | F51: =INDEX(' Balance Sheet'!$E$9:$G$40,MATCH('3 Statement Model'!$B51,' Balance Sheet'!$B$9:$B$40,0),MATCH('3 Statement Model'!F$9,' Balance Sheet'!$E$6:$G$6,0)) -> 6550.7708 | G51: =Schedules!F275 -> 7230.2267 | H51: =Schedules!G275 -> 7981.8188 | I51: =Schedules!H275 -> 8799.7041 | J51: =Schedules!I275 -> 9605.2603 | K51: =Schedules!J275 -> 10487.799
...

Sheet Common Size Statement
B2: Mrs Sector Foods
B3: Common Size Statement
F4: Current Case | G4: 1
D8: Actual | G8: Explicit Forecast Period
B9: In INR crores unless started otherwise | D9: 2021 | E9: =D9+1 -> 2022 | F9: =E9+1 -> 2023 | G9: =F9+1 -> 2024 | H9: =G9+1 -> 2025 | I9: =H9+1 -> 2026 | J9: =I9+1 -> 2027 | K9: =J9+1 -> 2028
A11: # | B11: Common Sized Income Statement
B13: Revenue | D13: ='3 Statement Model'!D13/'3 Statement Model'!D$13 -> 1 | E13: ='3 Statement Model'!E13/'3 Statement Model'!E$13 -> 1 | F13: ='3 Statement Model'!F13/'3 Statement Model'!F$13 -> 1 | G13: ='3 Statement Model'!G13/'3 Statement Model'!G$13 -> 1 | H13: ='3 Statement Model'!H13/'3 Statement Model'!H$13 -> 1 | I13: ='3 Statement Model'!I13/'3 Statement Model'!I$13 -> 1 | J13: ='3 Statement Model'!J13/'3 Statement Model'!J$13 -> 1 | K13: ='3 Statement Model'!K13/'3 Statement Model'!K$13 -> 1
B14: Less: Cost of Goods Sold | D14: ='3 Statement Model'!D14/'3 Statement Model'!D$13 -> -0.51200007 | E14: ='3 Statement Model'!E14/'3 Statement Model'!E$13 -> -0.50524035 | F14: ='3 Statement Model'!F14/'3 Statement Model'!F$13 -> -0.48454214 | G14: ='3 Statement Model'!G14/'3 Statement Model'!G$13 -> -0.47112862 | H14: ='3 Statement Model'!H14/'3 Statement Model'!H$13 -> -0.4579466 | I14: ='3 Statement Model'!I14/'3 Statement Model'!I$13 -> -0.44453708 | J14: ='3 Statement Model'!J14/'3 Statement Model'!J$13 -> -0.43135982 | K14: ='3 Statement Model'!K14/'3 Statement Model'!K$13 -> -0.41851846
B15: Gross Profit | D15: ='3 Statement Model'!D15/'3 Statement Model'!D$13 -> 0.48799993 | E15: ='3 Statement Model'!E15/'3 Statement Model'!E$13 -> 0.49475965 | F15: ='3 Statement Model'!F15/'3 Statement Model'!F$13 -> 0.51545786 | G15: ='3 Statement Model'!G15/'3 Statement Model'!G$13 -> 0.52887138 | H15: ='3 Statement Model'!H15/'3 Statement Model'!H$13 -> 0.5420534 | I15: ='3 Statement Model'!I15/'3 Statement Model'!I$13 -> 0.55546292 | J15: ='3 Statement Model'!J15/'3 Statement Model'!J$13 -> 0.56864018 | K15: ='3 Statement Model'!K15/'3 Statement Model'!K$13 -> 0.58148154
B17: Less: SG&A Expenses (Excluding Depreciation & Interest)
B18: Administrative Costs | D18: ='3 Statement Model'!D18/'3 Statement Model'!D$13 -> -0.0060279884 | E18: ='3 Statement Model'!E18/'3 Statement Model'!E$13 -> -0.0059885487 | F18: ='3 Statement Model'!F18/'3 Statement Model'!F$13 -> -0.0059884788 | G18: ='3 Statement Model'!G18/'3 Statement Model'!G$13 -> -0.01 | H18: ='3 Statement Model'!H18/'3 Statement Model'!H$13 -> -0.01 | I18: ='3 Statement Model'!I18/'3 Statement Model'!I$13 -> -0.01 | J18: ='3 Statement Model'!J18/'3 Statement Model'!J$13 -> -0.01 | K18: ='3 Statement Model'!K18/'3 Statement Model'!K$13 -> -0.01
B19: Executive Compensation | D19: ='3 Statement Model'!D19/'3 Statement Model'!D$13 -> -0.054999855 | E19: ='3 Statement Model'!E19/'3 Statement Model'!E$13 -> -0.051999694 | F19: ='3 Statement Model'!F19/'3 Statement Model'!F$13 -> -0.049999983 | G19: ='3 Statement Model'!G19/'3 Statement Model'!G$13 -> -0.053418287 | H19: ='3 Statement Model'!H19/'3 Statement Model'!H$13 -> -0.051637414 | I19: ='3 Statement Model'!I19/'3 Statement Model'!I$13 -> -0.050018859 | J19: ='3 Statement Model'!J19/'3 Statement Model'!J$13 -> -0.048706753 | K19: ='3 Statement Model'!K19/'3 Statement Model'!K$13 -> -0.047475248
B20: Marketing Costs | D20: ='3 Statement Model'!D20/'3 Statement Model'!D$13 -> -0.024999896 | E20: ='3 Statement Model'!E20/'3 Statement Model'!E$13 -> -0.024999767 | F20: ='3 Statement Model'!F20/'3 Statement Model'!F$13 -> -0.024999823 | G20: ='3 Statement Model'!G20/'3 Statement Model'!G$13 -> -0.025 | H20: ='3 Statement Model'!H20/'3 Statement Model'!H$13 -> -0.025 | I20: ='3 Statement Model'!I20/'3 Statement Model'!I$13 -> -0.025 | J20: ='3 Statement Model'!J20/'3 Statement Model'!J$13 -> -0.025 | K20: ='3 Statement Model'!K20/'3 Statement Model'!K$13 -> -0.025
B21: Rent | D21: ='3 Statement Model'!D21/'3 Statement Model'!D$13 -> -0.025713895 | E21: ='3 Statement Model'!E21/'3 Statement Model'!E$13 -> -0.023999687 | F21: ='3 Statement Model'!F21/'3 Statement Model'!F$13 -> -0.021944476 | G21: ='3 Statement Model'!G21/'3 Statement Model'!G$13 -> -0.019897891 | H21: ='3 Statement Model'!H21/'3 Statement Model'!H$13 -> -0.022268574 | I21: ='3 Statement Model'!I21/'3 Statement Model'!I$13 -> -0.020198829 | J21: ='3 Statement Model'!J21/'3 Statement Model'!J$13 -> -0.018504831 | K21: ='3 Statement Model'!K21/'3 Statement Model'!K$13 -> -0.016947666
B22: Retailer Commission | D22: ='3 Statement Model'!D22/'3 Statement Model'!D$13 -> -0.15000004 | E22: ='3 Statement Model'!E22/'3 Statement Model'!E$13 -> -0.14999972 | F22: ='3 Statement Model'!F22/'3 Statement Model'!F$13 -> -0.14999995 | G22: ='3 Statement Model'!G22/'3 Statement Model'!G$13 -> -0.15 | H22: ='3 Statement Model'!H22/'3 Statement Model'!H$13 -> -0.15 | I22: ='3 Statement Model'!I22/'3 Statement Model'!I$13 -> -0.15 | J22: ='3 Statement Model'!J22/'3 Statement Model'!J$13 -> -0.16 | K22: ='3 Statement Model'!K22/'3 Statement Model'!K$13 -> -0.16
B23: Salaries and Wages | D23: ='3 Statement Model'!D23/'3 Statement Model'!D$13 -> -0.10274086 | E23: ='3 Statement Model'!E23/'3 Statement Model'!E$13 -> -0.097999653 | F23: ='3 Statement Model'!F23/'3 Statement Model'!F$13 -> -0.098376075 | G23: ='3 Statement Model'!G23/'3 Statement Model'!G$13 -> -0.09 | H23: ='3 Statement Model'!H23/'3 Statement Model'!H$13 -> -0.09 | I23: ='3 Statement Model'!I23/'3 Statement Model'!I$13 -> -0.09 | J23: ='3 Statement Model'!J23/'3 Statement Model'!J$13 -> -0.09 | K23: ='3 Statement Model'!K23/'3 Statement Model'!K$13 -> -0.09
B24: EBITDA | D24: ='3 Statement Model'!D24/'3 Statement Model'!D$13 -> 0.1235174 | E24: ='3 Statement Model'!E24/'3 Statement Model'!E$13 -> 0.13977258 | F24: ='3 Statement Model'!F24/'3 Statement Model'!F$13 -> 0.16414907 | G24: ='3 Statement Model'!G24/'3 Statement Model'!G$13 -> 0.1805552 | H24: ='3 Statement Model'!H24/'3 Statement Model'!H$13 -> 0.19314741 | I24: ='3 Statement Model'!I24/'3 Statement Model'!I$13 -> 0.21024523 | J24: ='3 Statement Model'!J24/'3 Statement Model'!J$13 -> 0.21642859 | K24: ='3 Statement Model'!K24/'3 Statement Model'!K$13 -> 0.23205863
B26: Less: Depreciation & Amortization
B27: Depreciation | D27: ='3 Statement Model'!D27/'3 Statement Model'!D$13 -> -0.015131059 | E27: ='3 Statement Model'!E27/'3 Statement Model'!E$13 -> -0.013999631 | F27: ='3 Statement Model'!F27/'3 Statement Model'!F$13 -> -0.01349349 | G27: ='3 Statement Model'!G27/'3 Statement Model'!G$13 -> -0.01723506 | H27: ='3 Statement Model'!H27/'3 Statement Model'!H$13 -> -0.020612155 | I27: ='3 Statement Model'!I27/'3 Statement Model'!I$13 -> -0.023696366 | J27: ='3 Statement Model'!J27/'3 Statement Model'!J$13 -> -0.026709043 | K27: ='3 Statement Model'!K27/'3 Statement Model'!K$13 -> -0.0294615
B28: Amortization | D28: ='3 Statement Model'!D28/'3 Statement Model'!D$13 -> -0.0062209834 | E28: ='3 Statement Model'!E28/'3 Statement Model'!E$13 -> -0.0051167413 | F28: ='3 Statement Model'!F28/'3 Statement Model'!F$13 -> -0.0039999716 | G28: ='3 Statement Model'!G28/'3 Statement Model'!G$13 -> -0.0056269264 | H28: ='3 Statement Model'!H28/'3 Statement Model'!H$13 -> -0.007097078 | I28: ='3 Statement Model'!I28/'3 Statement Model'!I$13 -> -0.0084374427 | J28: ='3 Statement Model'!J28/'3 Statement Model'!J$13 -> -0.0097298268 | K28: ='3 Statement Model'!K28/'3 Statement Model'!K$13 -> -0.01091107
B29: EBIT | D29: ='3 Statement Model'!D29/'3 Statement Model'!D$13 -> 0.10216535 | E29: ='3 Statement Model'!E29/'3 Statement Model'!E$13 -> 0.1206562 | F29: ='3 Statement Model'!F29/'3 Statement Model'!F$13 -> 0.14665561 | G29: ='3 Statement Model'!G29/'3 Statement Model'!G$13 -> 0.15769321 | H29: ='3 Statement Model'!H29/'3 Statement Model'!H$13 -> 0.16543818 | I29: ='3 Statement Model'!I29/'3 Statement Model'!I$13 -> 0.17811142 | J29: ='3 Statement Model'!J29/'3 Statement Model'!J$13 -> 0.17998972 | K29: ='3 Statement Model'!K29/'3 Statement Model'!K$13 -> 0.19168606
B31: Less: Total Interest Expenses
B32: Loan Interest Expenses | D32: ='3 Statement Model'!D32/'3 Statement Model'!D$13 -> -0.00711928 | E32: ='3 Statement Model'!E32/'3 Statement Model'!E$13 -> -0.0058561742 | F32: ='3 Statement Model'!F32/'3 Statement Model'!F$13 -> -0.0048007762 | G32: ='3 Statement Model'!G32/'3 Statement Model'!G$13 -> -0.010201452 | H32: ='3 Statement Model'!H32/'3 Statement Model'!H$13 -> -0.010003236 | I32: ='3 Statement Model'!I32/'3 Statement Model'!I$13 -> -0.009411212 | J32: ='3 Statement Model'!J32/'3 Statement Model'!J$13 -> -0.0086195456 | K32: ='3 Statement Model'!K32/'3 Statement Model'!K$13 -> -0.0078864358
B33: Rovolver Interest | D33: ='3 Statement Model'!D33/'3 Statement Model'!D$13 -> 0 | E33: ='3 Statement Model'!E33/'3 Statement Model'!E$13 -> 0 | F33: ='3 Statement Model'!F33/'3 Statement Model'!F$13 -> 0 | G33: ='3 Statement Model'!G33/'3 Statement Model'!G$13 -> 0 | H33: ='3 Statement Model'!H33/'3 Statement Model'!H$13 -> 0 | I33: ='3 Statement Model'!I33/'3 Statement Model'!I$13 -> 0 | J33: ='3 Statement Model'!J33/'3 Statement Model'!J$13 -> 0 | K33: ='3 Statement Model'!K33/'3 Statement Model'!K$13 -> 0
B34: EBT | D34: ='3 Statement Model'!D34/'3 Statement Model'!D$13 -> 0.095046074 | E34: ='3 Statement Model'!E34/'3 Statement Model'!E$13 -> 0.11480003 | F34: ='3 Statement Model'!F34/'3 Statement Model'!F$13 -> 0.14185483 | G34: ='3 Statement Model'!G34/'3 Statement Model'!G$13 -> 0.14749176 | H34: ='3 Statement Model'!H34/'3 Statement Model'!H$13 -> 0.15543494 | I34: ='3 Statement Model'!I34/'3 Statement Model'!I$13 -> 0.16870021 | J34: ='3 Statement Model'!J34/'3 Statement Model'!J$13 -> 0.17137018 | K34: ='3 Statement Model'!K34/'3 Statement Model'!K$13 -> 0.18379962
B36: Less: Taxes | D36: ='3 Statement Model'!D36/'3 Statement Model'!D$13 -> -0.019151784 | E36: ='3 Statement Model'!E36/'3 Statement Model'!E$13 -> -0.023132206 | F36: ='3 Statement Model'!F36/'3 Statement Model'!F$13 -> -0.028583749 | G36: ='3 Statement Model'!G36/'3 Statement Model'!G$13 -> -0.03687294 | H36: ='3 Statement Model'!H36/'3 Statement Model'!H$13 -> -0.038858736 | I36: ='3 Statement Model'!I36/'3 Statement Model'!I$13 -> -0.042175053 | J36: ='3 Statement Model'!J36/'3 Statement Model'!J$13 -> -0.042842544 | K36: ='3 Statement Model'!K36/'3 Statement Model'!K$13 -> -0.045949905
B37: Net Income | D37: ='3 Statement Model'!D37/'3 Statement Model'!D$13 -> 0.07589429 | E37: ='3 Statement Model'!E37/'3 Statement Model'!E$13 -> 0.091667824 | F37: ='3 Statement Model'!F37/'3 Statement Model'!F$13 -> 0.11327109 | G37: ='3 Statement Model'!G37/'3 Statement Model'!G$13 -> 0.11061882 | H37: ='3 Statement Model'!H37/'3 Statement Model'!H$13 -> 0.11657621 | I37: ='3 Statement Model'!I37/'3 Statement Model'!I$13 -> 0.12652516 | J37: ='3 Statement Model'!J37/'3 Statement Model'!J$13 -> 0.12852763 | K37: ='3 Statement Model'!K37/'3 Statement Model'!K$13 -> 0.13784971
A39: # | B39: Common Sized Balance Sheet
B41: Assets
B42: Cash | D42: ='3 Statement Model'!D49/'3 Statement Model'!D$62 -> 0.061225988 | E42: ='3 Statement Model'!E49/'3 Statement Model'!E$62 -> 0.070390974 | F42: ='3 Statement Model'!F49/'3 Statement Model'!F$62 -> 0.070741653 | G42: ='3 Statement Model'!G49/'3 Statement Model'!G$62 -> 0.091450866 | H42: ='3 Statement Model'!H49/'3 Statement Model'!H$62 -> 0.11935231 | I42: ='3 Statement Model'!I49/'3 Statement Model'!I$62 -> 0.14830644 | J42: ='3 Statement Model'!J49/'3 Statement Model'!J$62 -> 0.18078498 | K42: ='3 Statement Model'!K49/'3 Statement Model'!K$62 -> 0.21946478
B43: Inventory | D43: ='3 Statement Model'!D50/'3 Statement Model'!D$62 -> 0.19504339 | E43: ='3 Statement Model'!E50/'3 Statement Model'!E$62 -> 0.18552581 | F43: ='3 Statement Model'!F50/'3 Statement Model'!F$62 -> 0.18137715 | G43: ='3 Statement Model'!G50/'3 Statement Model'!G$62 -> 0.16206047 | H43: ='3 Statement Model'!H50/'3 Statement Model'!H$62 -> 0.14616597 | I43: ='3 Statement Model'!I50/'3 Statement Model'!I$62 -> 0.13312376 | J43: ='3 Statement Model'!J50/'3 Statement Model'!J$62 -> 0.12130169 | K43: ='3 Statement Model'!K50/'3 Statement Model'!K$62 -> 0.11052759
B44: Debtors | D44: ='3 Statement Model'!D51/'3 Statement Model'!D$62 -> 0.22789741 | E44: ='3 Statement Model'!E51/'3 Statement Model'!E$62 -> 0.21677675 | F44: ='3 Statement Model'!F51/'3 Statement Model'!F$62 -> 0.21245125 | G44: ='3 Statement Model'!G51/'3 Statement Model'!G$62 -> 0.19526589 | H44: ='3 Statement Model'!H51/'3 Statement Model'!H$62 -> 0.18118415 | I44: ='3 Statement Model'!I51/'3 Statement Model'!I$62 -> 0.16999508 | J44: ='3 Statement Model'!J51/'3 Statement Model'!J$62 -> 0.15963052 | K44: ='3 Statement Model'!K51/'3 Statement Model'!K$62 -> 0.14991492
B45: Prepaid Expenses | D45: ='3 Statement Model'!D52/'3 Statement Model'!D$62 -> 0.069087332 | E45: ='3 Statement Model'!E52/'3 Statement Model'!E$62 -> 0.06891684 | F45: ='3 Statement Model'!F52/'3 Statement Model'!F$62 -> 0.070927265 | G45: ='3 Statement Model'!G52/'3 Statement Model'!G$62 -> 0.065189898 | H45: ='3 Statement Model'!H52/'3 Statement Model'!H$62 -> 0.060488683 | I45: ='3 Statement Model'!I52/'3 Statement Model'!I$62 -> 0.056753188 | J45: ='3 Statement Model'!J52/'3 Statement Model'!J$62 -> 0.05329296 | K45: ='3 Statement Model'!K52/'3 Statement Model'!K$62 -> 0.050049387
B46: Other Current Assets | D46: ='3 Statement Model'!D53/'3 Statement Model'!D$62 -> 0.0040619935 | E46: ='3 Statement Model'!E53/'3 Statement Model'!E$62 -> 0.004678437 | F46: ='3 Statement Model'!F53/'3 Statement Model'!F$62 -> 0.0049021882 | G46: ='3 Statement Model'!G53/'3 Statement Model'!G$62 -> 0.004505646 | H46: ='3 Statement Model'!H53/'3 Statement Model'!H$62 -> 0.0041807182 | I46: ='3 Statement Model'!I53/'3 Statement Model'!I$62 -> 0.0039225369 | J46: ='3 Statement Model'!J53/'3 Statement Model'!J$62 -> 0.0036833808 | K46: ='3 Statement Model'!K53/'3 Statement Model'!K$62 -> 0.0034591989
B47: Total Current Assets | D47: ='3 Statement Model'!D54/'3 Statement Model'!D$62 -> 0.55731612 | E47: ='3 Statement Model'!E54/'3 Statement Model'!E$62 -> 0.54628881 | F47: ='3 Statement Model'!F54/'3 Statement Model'!F$62 -> 0.54039951 | G47: ='3 Statement Model'!G54/'3 Statement Model'!G$62 -> 0.51847277 | H47: ='3 Statement Model'!H54/'3 Statement Model'!H$62 -> 0.51137184 | I47: ='3 Statement Model'!I54/'3 Statement Model'!I$62 -> 0.51210101 | J47: ='3 Statement Model'!J54/'3 Statement Model'!J$62 -> 0.51869354 | K47: ='3 Statement Model'!K54/'3 Statement Model'!K$62 -> 0.53341587
B49: Net Property, Plant & Equipment | D49: ='3 Statement Model'!D56/'3 Statement Model'!D$62 -> 0.29159893 | E49: ='3 Statement Model'!E56/'3 Statement Model'!E$62 -> 0.29902005 | F49: ='3 Statement Model'!F56/'3 Statement Model'!F$62 -> 0.30781699 | G49: ='3 Statement Model'!G56/'3 Statement Model'!G$62 -> 0.31298647 | H49: ='3 Statement Model'!H56/'3 Statement Model'!H$62 -> 0.31022068 | I49: ='3 Statement Model'!I56/'3 Statement Model'!I$62 -> 0.30360721 | J49: ='3 Statement Model'!J56/'3 Statement Model'!J$62 -> 0.2941105 | K49: ='3 Statement Model'!K56/'3 Statement Model'!K$62 -> 0.28023336
B50: Net Intangible Assets | D50: ='3 Statement Model'!D57/'3 Statement Model'!D$62 -> 0.10404168 | E50: ='3 Statement Model'!E57/'3 Statement Model'!E$62 -> 0.093495527 | F50: ='3 Statement Model'!F57/'3 Statement Model'!F$62 -> 0.092577749 | G50: ='3 Statement Model'!G57/'3 Statement Model'!G$62 -> 0.11923797 | H50: ='3 Statement Model'!H57/'3 Statement Model'!H$62 -> 0.13696791 | I50: ='3 Statement Model'!I57/'3 Statement Model'!I$62 -> 0.14902505 | J50: ='3 Statement Model'!J57/'3 Statement Model'!J$62 -> 0.15685679 | K50: ='3 Statement Model'!K57/'3 Statement Model'!K$62 -> 0.16025576
B51: Goodwill | D51: ='3 Statement Model'!D58/'3 Statement Model'!D$62 -> 0 | E51: ='3 Statement Model'!E58/'3 Statement Model'!E$62 -> 0 | F51: ='3 Statement Model'!F58/'3 Statement Model'!F$62 -> 0 | G51: ='3 Statement Model'!G58/'3 Statement Model'!G$62 -> 0 | H51: ='3 Statement Model'!H58/'3 Statement Model'!H$62 -> 0 | I51: ='3 Statement Model'!I58/'3 Statement Model'!I$62 -> 0 | J51: ='3 Statement Model'!J58/'3 Statement Model'!J$62 -> 0 | K51: ='3 Statement Model'!K58/'3 Statement Model'!K$62 -> 0
B52: Other Non-Current Assets | D52: ='3 Statement Model'!D59/'3 Statement Model'!D$62 -> 0.047043268 | E52: ='3 Statement Model'!E59/'3 Statement Model'!E$62 -> 0.06119562 | F52: ='3 Statement Model'!F59/'3 Statement Model'!F$62 -> 0.059205746 | G52: ='3 Statement Model'!G59/'3 Statement Model'!G$62 -> 0.049302783 | H52: ='3 Statement Model'!H59/'3 Statement Model'!H$62 -> 0.041439577 | I52: ='3 Statement Model'!I59/'3 Statement Model'!I$62 -> 0.035266735 | J52: ='3 Statement Model'!J59/'3 Statement Model'!J$62 -> 0.030339174 | K52: ='3 Statement Model'!K59/'3 Statement Model'!K$62 -> 0.026095008
B53: Total Non-Current Assets | D53: ='3 Statement Model'!D60/'3 Statement Model'!D$62 -> 0.44268388 | E53: ='3 Statement Model'!E60/'3 Statement Model'!E$62 -> 0.45371119 | F53: ='3 Statement Model'!F60/'3 Statement Model'!F$62 -> 0.45960049 | G53: ='3 Statement Model'!G60/'3 Statement Model'!G$62 -> 0.48152723 | H53: ='3 Statement Model'!H60/'3 Statement Model'!H$62 -> 0.48862816 | I53: ='3 Statement Model'!I60/'3 Statement Model'!I$62 -> 0.48789899 | J53: ='3 Statement Model'!J60/'3 Statement Model'!J$62 -> 0.48130646 | K53: ='3 Statement Model'!K60/'3 Statement Model'!K$62 -> 0.46658413
...

Sheet Ratio Analysis
B2: Mrs Sector Foods
B3: Ratio Analysis
F4: Current Case | G4: 1
D8: Actual | G8: Explicit Forecast Period
B9: In INR crores unless started otherwise | D9: 2021 | E9: =D9+1 -> 2022 | F9: =E9+1 -> 2023 | G9: =F9+1 -> 2024 | H9: =G9+1 -> 2025 | I9: =H9+1 -> 2026 | J9: =I9+1 -> 2027 | K9: =J9+1 -> 2028
A11: # | B11: Liquidity Ratio
B13: Current Asset | D13: ='3 Statement Model'!D54 -> 13392.072 | E13: ='3 Statement Model'!E54 -> 15180.553 | F13: ='3 Statement Model'!F54 -> 16662.803 | G13: ='3 Statement Model'!G54 -> 19197.801 | H13: ='3 Statement Model'!H54 -> 22527.783 | I13: ='3 Statement Model'!I54 -> 26508.634 | J13: ='3 Statement Model'!J54 -> 31210.739 | K13: ='3 Statement Model'!K54 -> 37316.891
B14: Current Liabilities | D14: ='3 Statement Model'!D69 -> 7506.898 | E14: ='3 Statement Model'!E69 -> 8673.7056 | F14: ='3 Statement Model'!F69 -> 9658.5272 | G14: ='3 Statement Model'!G69 -> 10474.089 | H14: ='3 Statement Model'!H69 -> 11362.184 | I14: ='3 Statement Model'!I69 -> 12301.363 | J14: ='3 Statement Model'!J69 -> 13186.038 | K14: ='3 Statement Model'!K69 -> 14140.682
B15: Current Ratio | D15: =D13/D14 -> 1.7839689 | E15: =E13/E14 -> 1.7501808 | F15: =F13/F14 -> 1.7251909 | G15: =G13/G14 -> 1.832885 | H15: =H13/H14 -> 1.9826984 | I15: =I13/I14 -> 2.1549346 | J15: =J13/J14 -> 2.3669535 | K15: =K13/K14 -> 2.6389739
B17: Current Asset | D17: ='3 Statement Model'!D54 -> 13392.072 | E17: ='3 Statement Model'!E54 -> 15180.553 | F17: ='3 Statement Model'!F54 -> 16662.803 | G17: ='3 Statement Model'!G54 -> 19197.801 | H17: ='3 Statement Model'!H54 -> 22527.783 | I17: ='3 Statement Model'!I54 -> 26508.634 | J17: ='3 Statement Model'!J54 -> 31210.739 | K17: ='3 Statement Model'!K54 -> 37316.891
B18: Inventory | D18: ='3 Statement Model'!D50 -> 4686.8108 | E18: ='3 Statement Model'!E50 -> 5155.486 | F18: ='3 Statement Model'!F50 -> 5592.6248 | G18: ='3 Statement Model'!G50 -> 6000.7099 | H18: ='3 Statement Model'!H50 -> 6439.141 | I18: ='3 Statement Model'!I50 -> 6891.08 | J18: ='3 Statement Model'!J50 -> 7298.9445 | K18: ='3 Statement Model'!K50 -> 7732.3272
B19: Prepaid Expenses | D19: ='3 Statement Model'!D52 -> 1660.1396 | E19: ='3 Statement Model'!E52 -> 1915.0964 | F19: ='3 Statement Model'!F52 -> 2186.9876 | G19: ='3 Statement Model'!G52 -> 2413.8253 | H19: ='3 Statement Model'!H52 -> 2664.7458 | I19: ='3 Statement Model'!I52 -> 2937.7984 | J19: ='3 Statement Model'!J52 -> 3206.7349 | K19: ='3 Statement Model'!K52 -> 3501.3723
B20: Current Liabilities | D20: ='3 Statement Model'!D69 -> 7506.898 | E20: ='3 Statement Model'!E69 -> 8673.7056 | F20: ='3 Statement Model'!F69 -> 9658.5272 | G20: ='3 Statement Model'!G69 -> 10474.089 | H20: ='3 Statement Model'!H69 -> 11362.184 | I20: ='3 Statement Model'!I69 -> 12301.363 | J20: ='3 Statement Model'!J69 -> 13186.038 | K20: ='3 Statement Model'!K69 -> 14140.682
B21: Quick Ratio (Acid Test) | D21: =(D17-D18-D19)/D20 -> 0.93848644 | E21: =(E17-E18-E19)/E20 -> 0.93500642 | F21: =(F17-F18-F19)/F20 -> 0.91972515 | G21: =(G17-G18-G19)/G20 -> 1.0295182 | H21: =(H17-H18-H19)/H20 -> 1.181454 | I21: =(I17-I18-I19)/I20 -> 1.3559274 | J21: =(J17-J18-J19)/J20 -> 1.570226 | K21: =(K17-K18-K19)/K20 -> 1.8445497
B23: Inventory Days | D23: ='3 Statement Model'!D86 -> 70.599951 | E23: ='3 Statement Model'!E86 -> 70.85727 | F23: ='3 Statement Model'!F86 -> 72.565934 | G23: ='3 Statement Model'!G86 -> 72.609531 | H23: ='3 Statement Model'!H86 -> 72.609531 | I23: ='3 Statement Model'!I86 -> 72.609531 | J23: ='3 Statement Model'!J86 -> 72.609531 | K23: ='3 Statement Model'!K86 -> 72.609531
B24: Debtor Days | D24: ='3 Statement Model'!D85 -> 42.23598 | E24: ='3 Statement Model'!E85 -> 41.830285 | F24: ='3 Statement Model'!F85 -> 41.185189 | G24: ='3 Statement Model'!G85 -> 41.217572 | H24: ='3 Statement Model'!H85 -> 41.217572 | I24: ='3 Statement Model'!I85 -> 41.217572 | J24: ='3 Statement Model'!J85 -> 41.217572 | K24: ='3 Statement Model'!K85 -> 41.217572
B25: Creditor Days | D25: ='3 Statement Model'!D87 -> 70.664609 | E25: ='3 Statement Model'!E87 -> 74.174458 | F25: ='3 Statement Model'!F87 -> 78.575923 | G25: ='3 Statement Model'!G87 -> 78.623131 | H25: ='3 Statement Model'!H87 -> 78.623131 | I25: ='3 Statement Model'!I87 -> 78.623131 | J25: ='3 Statement Model'!J87 -> 78.623131 | K25: ='3 Statement Model'!K87 -> 78.623131
B26: Cash Conversion Days | D26: =D23+D24-D25 -> 42.171321 | E26: =E23+E24-E25 -> 38.513097 | F26: =F23+F24-F25 -> 35.1752 | G26: =G23+G24-G25 -> 35.203972 | H26: =H23+H24-H25 -> 35.203972 | I26: =I23+I24-I25 -> 35.203972 | J26: =J23+J24-J25 -> 35.203972 | K26: =K23+K24-K25 -> 35.203972
A28: # | B28: Leverage Ratio / Solvency Ratio
B30: Total Debt | D30: =SUM('3 Statement Model'!D71:D72) -> 7487.2 | E30: =SUM('3 Statement Model'!E71:E72) -> 6840.4 | F30: =SUM('3 Statement Model'!F71:F72) -> 6193.6 | G30: =SUM('3 Statement Model'!G71:G72) -> 6613.6 | H30: =SUM('3 Statement Model'!H71:H72) -> 6983.6 | I30: =SUM('3 Statement Model'!I71:I72) -> 6853.6 | J30: =SUM('3 Statement Model'!J71:J72) -> 6723.6 | K30: =SUM('3 Statement Model'!K71:K72) -> 6593.6
B31: Total Equity | D31: ='3 Statement Model'!D78 -> 8586.0544 | E31: ='3 Statement Model'!E78 -> 10467.325 | F31: ='3 Statement Model'!F78 -> 14078.562 | G31: ='3 Statement Model'!G78 -> 19036.367 | H31: ='3 Statement Model'!H78 -> 24804.301 | I31: ='3 Statement Model'!I78 -> 31705.96 | J31: ='3 Statement Model'!J78 -> 39358.65 | K31: ='3 Statement Model'!K78 -> 48320.523
B32: Debt to Equity Ratio | D32: =D30/D31 -> 0.8720187 | E32: =E30/E31 -> 0.65350029 | F32: =F30/F31 -> 0.43993128 | G32: =G30/G31 -> 0.34741923 | H32: =H30/H31 -> 0.28154794 | I32: =I30/I31 -> 0.21616125 | J32: =J30/J31 -> 0.17082903 | K32: =K30/K31 -> 0.13645548
B34: Total Debt | D34: =SUM('3 Statement Model'!D71:D72) -> 7487.2 | E34: =SUM('3 Statement Model'!E71:E72) -> 6840.4 | F34: =SUM('3 Statement Model'!F71:F72) -> 6193.6 | G34: =SUM('3 Statement Model'!G71:G72) -> 6613.6 | H34: =SUM('3 Statement Model'!H71:H72) -> 6983.6 | I34: =SUM('3 Statement Model'!I71:I72) -> 6853.6 | J34: =SUM('3 Statement Model'!J71:J72) -> 6723.6 | K34: =SUM('3 Statement Model'!K71:K72) -> 6593.6
B35: Total Asset | D35: ='3 Statement Model'!D62 -> 24029.58 | E35: ='3 Statement Model'!E62 -> 27788.512 | F35: ='3 Statement Model'!F62 -> 30834.23 | G35: ='3 Statement Model'!G62 -> 37027.597 | H35: ='3 Statement Model'!H62 -> 44053.625 | I35: ='3 Statement Model'!I62 -> 51764.464 | J35: ='3 Statement Model'!J62 -> 60171.829 | K35: ='3 Statement Model'!K62 -> 69958.345
B36: Debt to Asset Ratio | D36: =D34/D35 -> 0.31158264 | E36: =E34/E35 -> 0.24615928 | F36: =F34/F35 -> 0.20086767 | G36: =G34/G35 -> 0.17861272 | H36: =H34/H35 -> 0.15852498 | I36: =I34/I35 -> 0.13239971 | J36: =J34/J35 -> 0.11174 | K36: =K34/K35 -> 0.094250371
B38: Total Equity | D38: ='3 Statement Model'!D78 -> 8586.0544 | E38: ='3 Statement Model'!E78 -> 10467.325 | F38: ='3 Statement Model'!F78 -> 14078.562 | G38: ='3 Statement Model'!G78 -> 19036.367 | H38: ='3 Statement Model'!H78 -> 24804.301 | I38: ='3 Statement Model'!I78 -> 31705.96 | J38: ='3 Statement Model'!J78 -> 39358.65 | K38: ='3 Statement Model'!K78 -> 48320.523
B39: Total Asset | D39: ='3 Statement Model'!D62 -> 24029.58 | E39: ='3 Statement Model'!E62 -> 27788.512 | F39: ='3 Statement Model'!F62 -> 30834.23 | G39: ='3 Statement Model'!G62 -> 37027.597 | H39: ='3 Statement Model'!H62 -> 44053.625 | I39: ='3 Statement Model'!I62 -> 51764.464 | J39: ='3 Statement Model'!J62 -> 60171.829 | K39: ='3 Statement Model'!K62 -> 69958.345
B40: Equity To Asset Ratio | D40: =D38/D39 -> 0.35731187 | E40: =E38/E39 -> 0.37667815 | F40: =F38/F39 -> 0.45658875 | G40: =G38/G39 -> 0.51411295 | H40: =H38/H39 -> 0.5630479 | I40: =I38/I39 -> 0.61250436 | J40: =J38/J39 -> 0.65410427 | K40: =K38/K39 -> 0.69070419
A42: # | B42: Profitability Ratio
B44: Gross Profit | D44: ='3 Statement Model'!D15 -> 23094.876 | E44: ='3 Statement Model'!E15 -> 26006.044 | F44: ='3 Statement Model'!F15 -> 29925.221 | G44: ='3 Statement Model'!G15 -> 33861.987 | H44: ='3 Statement Model'!H15 -> 38313.727 | I44: ='3 Statement Model'!I15 -> 43284.619 | J44: ='3 Statement Model'!J15 -> 48367.89 | K44: ='3 Statement Model'!K15 -> 54004.602
B45: Total Sales | D45: ='3 Statement Model'!D13 -> 47325.572 | E45: ='3 Statement Model'!E13 -> 52562.986 | F45: ='3 Statement Model'!F13 -> 58055.612 | G45: ='3 Statement Model'!G13 -> 64026.885 | H45: ='3 Statement Model'!H13 -> 70682.569 | I45: ='3 Statement Model'!I13 -> 77925.308 | J45: ='3 Statement Model'!J13 -> 85058.869 | K45: ='3 Statement Model'!K13 -> 92874.147
B46: Gross Profit Margin | D46: =D44/D45 -> 0.48799993 | E46: =E44/E45 -> 0.49475965 | F46: =F44/F45 -> 0.51545786 | G46: =G44/G45 -> 0.52887138 | H46: =H44/H45 -> 0.5420534 | I46: =I44/I45 -> 0.55546292 | J46: =J44/J45 -> 0.56864018 | K46: =K44/K45 -> 0.58148154
B48: EBITDA | D48: ='3 Statement Model'!D24 -> 5845.5314 | E48: ='3 Statement Model'!E24 -> 7346.864 | F48: ='3 Statement Model'!F24 -> 9529.7748 | G48: ='3 Statement Model'!G24 -> 11560.387 | H48: ='3 Statement Model'!H24 -> 13652.155 | I48: ='3 Statement Model'!I24 -> 16383.425 | J48: ='3 Statement Model'!J24 -> 18409.171 | K48: ='3 Statement Model'!K24 -> 21552.247
B49: Total Sales | D49: ='3 Statement Model'!D13 -> 47325.572 | E49: ='3 Statement Model'!E13 -> 52562.986 | F49: ='3 Statement Model'!F13 -> 58055.612 | G49: ='3 Statement Model'!G13 -> 64026.885 | H49: ='3 Statement Model'!H13 -> 70682.569 | I49: ='3 Statement Model'!I13 -> 77925.308 | J49: ='3 Statement Model'!J13 -> 85058.869 | K49: ='3 Statement Model'!K13 -> 92874.147
B50: EBITDA Margin | D50: =D48/D49 -> 0.1235174 | E50: =E48/E49 -> 0.13977258 | F50: =F48/F49 -> 0.16414907 | G50: =G48/G49 -> 0.1805552 | H50: =H48/H49 -> 0.19314741 | I50: =I48/I49 -> 0.21024523 | J50: =J48/J49 -> 0.21642859 | K50: =K48/K49 -> 0.23205863
B52: EBIT | D52: ='3 Statement Model'!D29 -> 4835.0338 | E52: ='3 Statement Model'!E29 -> 6342.0504 | F52: ='3 Statement Model'!F29 -> 8514.1812 | G52: ='3 Statement Model'!G29 -> 10096.605 | H52: ='3 Statement Model'!H29 -> 11693.596 | I52: ='3 Statement Model'!I29 -> 13879.388 | J52: ='3 Statement Model'!J29 -> 15309.722 | K52: ='3 Statement Model'!K29 -> 17802.679
B53: Total Sales | D53: ='3 Statement Model'!D13 -> 47325.572 | E53: ='3 Statement Model'!E13 -> 52562.986 | F53: ='3 Statement Model'!F13 -> 58055.612 | G53: ='3 Statement Model'!G13 -> 64026.885 | H53: ='3 Statement Model'!H13 -> 70682.569 | I53: ='3 Statement Model'!I13 -> 77925.308 | J53: ='3 Statement Model'!J13 -> 85058.869 | K53: ='3 Statement Model'!K13 -> 92874.147
B54: EBIT Margin | D54: =D52/D53 -> 0.10216535 | E54: =E52/E53 -> 0.1206562 | F54: =F52/F53 -> 0.14665561 | G54: =G52/G53 -> 0.15769321 | H54: =H52/H53 -> 0.16543818 | I54: =I52/I53 -> 0.17811142 | J54: =J52/J53 -> 0.17998972 | K54: =K52/K53 -> 0.19168606
B56: Net Profit | D56: ='3 Statement Model'!D37 -> 3591.7407 | E56: ='3 Statement Model'!E37 -> 4818.3346 | F56: ='3 Statement Model'!F37 -> 6576.0222 | G56: ='3 Statement Model'!G37 -> 7082.5784 | H56: ='3 Statement Model'!H37 -> 8239.9059 | I56: ='3 Statement Model'!I37 -> 9859.512 | J56: ='3 Statement Model'!J37 -> 10932.415 | K56: ='3 Statement Model'!K37 -> 12802.675
B57: Total Sales | D57: ='3 Statement Model'!D13 -> 47325.572 | E57: ='3 Statement Model'!E13 -> 52562.986 | F57: ='3 Statement Model'!F13 -> 58055.612 | G57: ='3 Statement Model'!G13 -> 64026.885 | H57: ='3 Statement Model'!H13 -> 70682.569 | I57: ='3 Statement Model'!I13 -> 77925.308 | J57: ='3 Statement Model'!J13 -> 85058.869 | K57: ='3 Statement Model'!K13 -> 92874.147
...

Sheet DCF Val
B2: Mrs Sector Foods
B3: Common Size Statement
E4: Current Case | F4: 1
F8: Explicit Forecast Period
B9: In INR crores unless started otherwise | E9: ='Common Size Statement'!F9 -> 2023 | F9: =E9+1 -> 2024 | G9: =F9+1 -> 2025 | H9: =G9+1 -> 2026 | I9: =H9+1 -> 2027 | J9: =I9+1 -> 2028
A11: # | B11: Free Cash Flow to Firm
B13: EBITDA | F13: ='3 Statement Model'!G24 -> 11560.387 | G13: ='3 Statement Model'!H24 -> 13652.155 | H13: ='3 Statement Model'!I24 -> 16383.425 | I13: ='3 Statement Model'!J24 -> 18409.171 | J13: ='3 Statement Model'!K24 -> 21552.247
B14: Less: Depreciation | F14: ='3 Statement Model'!G27 -> -1103.5072 | G14: ='3 Statement Model'!H27 -> -1456.9201 | H14: ='3 Statement Model'!I27 -> -1846.5466 | I14: ='3 Statement Model'!J27 -> -2271.841 | J14: ='3 Statement Model'!K27 -> -2736.2117
B15: Less: Amortization | F15: ='3 Statement Model'!G28 -> -360.27457 | G15: ='3 Statement Model'!H28 -> -501.63971 | H15: ='3 Statement Model'!I28 -> -657.49033 | I15: ='3 Statement Model'!J28 -> -827.60806 | J15: ='3 Statement Model'!K28 -> -1013.3564
B16: EBIT | F16: =SUM(F13:F15) -> 10096.605 | G16: =SUM(G13:G15) -> 11693.596 | H16: =SUM(H13:H15) -> 13879.388 | I16: =SUM(I13:I15) -> 15309.722 | J16: =SUM(J13:J15) -> 17802.679
B17: Less: Tax | F17: ='3 Statement Model'!G36 -> -2360.8595 | G17: ='3 Statement Model'!H36 -> -2746.6353 | H17: ='3 Statement Model'!I36 -> -3286.504 | I17: ='3 Statement Model'!J36 -> -3644.1383 | J17: ='3 Statement Model'!K36 -> -4267.5582
B18: EBIT (1-T) | F18: =SUM(F16:F17) -> 7735.7456 | G18: =SUM(G16:G17) -> 8946.9603 | H18: =SUM(H16:H17) -> 10592.884 | I18: =SUM(I16:I17) -> 11665.584 | J18: =SUM(J16:J17) -> 13535.121
B19: Add: Depreciation | F19: =F14*-1 -> 1103.5072 | G19: =G14*-1 -> 1456.9201 | H19: =H14*-1 -> 1846.5466 | I19: =I14*-1 -> 2271.841 | J19: =J14*-1 -> 2736.2117
B20: Add: Amortization | F20: =F15*-1 -> 360.27457 | G20: =G15*-1 -> 501.63971 | H20: =H15*-1 -> 657.49033 | I20: =I15*-1 -> 827.60806 | J20: =J15*-1 -> 1013.3564
B22: Less: Reinvestment
B23: Change in Working Capital | F23: ='3 Statement Model'!G100 -> -514.49445 | G23: ='3 Statement Model'!H100 -> -570.19216 | H23: ='3 Statement Model'!I100 -> -622.56916 | I23: ='3 Statement Model'!J100 -> -616.27047 | J23: ='3 Statement Model'!K100 -> -676.27901
B24: Tangible Non Current Spend | F24: ='3 Statement Model'!G103 -> -3201.3443 | G24: ='3 Statement Model'!H103 -> -3534.1285 | H24: ='3 Statement Model'!I103 -> -3896.2654 | I24: ='3 Statement Model'!J103 -> -4252.9434 | J24: ='3 Statement Model'!K103 -> -4643.7073
B25: Intangible Non Current Spend | F25: ='3 Statement Model'!G104 -> -1920.8066 | G25: ='3 Statement Model'!H104 -> -2120.4771 | H25: ='3 Statement Model'!I104 -> -2337.7592 | I25: ='3 Statement Model'!J104 -> -2551.7661 | J25: ='3 Statement Model'!K104 -> -2786.2244
B26: Free Cash Flow to Firm | F26: =F18+F19+F20+F23+F24+F25 -> 3562.8821 | G26: =G18+G19+G20+G23+G24+G25 -> 4680.7224 | H26: =H18+H19+H20+H23+H24+H25 -> 6240.3267 | I26: =I18+I19+I20+I23+I24+I25 -> 7344.0529 | J26: =J18+J19+J20+J23+J24+J25 -> 9178.4779
B28: Discount Period (Year) | C28: Mid Year Convention? | D28: Yes | F28: =IF(D28="Yes",(F9-E9)/2,F9-E9) -> 0.5 | G28: =F28+1 -> 1.5 | H28: =G28+1 -> 2.5 | I28: =H28+1 -> 3.5 | J28: =I28+1 -> 4.5
B29: Discount Rate (WACC) | C29: =C45 -> 0.11048
